<?xml version="1.0" ?>

<sdf version="1.6">
    <model name="swerve">
        <link name="base_link">
        <pose> 0 0 0 0 0 0</pose>
        <inertial>
            <inertia>
                <ixx>1</ixx>
                <ixy>0</ixy>
                <ixz>0</ixz>
                <iyy>1</iyy>
                <iyz>0</iyz>
                <izz>1</izz>
            </inertia>
            <mass>1.0</mass>
        </inertial>

        <collision name="collision">
        <geometry>
        <mesh>
            <scale>1 1 1</scale>
            <uri>package://inrof_sim/models/swerve/meshs/swerve_base.stl</uri>
        </mesh>
        </geometry>
        <surface>
            <friction>
                <ode>
                    <mu>0.3</mu>
                    <mu2>0.3</mu2>
                </ode>
            </friction>
        </surface>
        </collision>

        <visual name="visual">
        <geometry>
        <mesh>
            <scale>1 1 1</scale>
            <uri>package://inrof_sim/models/swerve/meshs/swerve_base.stl</uri>
        </mesh>
        </geometry>
        <material>
            <ambient>0.0 0.0 1.0 1.0</ambient>   <diffuse>0.0 0.0 1.0 1.0</diffuse>   <specular>0.1 0.1 0.1 1.0</specular> <emissive>0.0 0.0 0.0 0.0</emissive>
        </material>
        </visual>
        </link>

        <link name="wheel0">
        <pose>0.27 0.155885 0 0 0 0</pose>
        <inertial>
            <inertia>
                <ixx>1</ixx>
                <ixy>0</ixy>
                <ixz>0</ixz>
                <iyy>1</iyy>
                <iyz>0</iyz>
                <izz>1</izz>
            </inertia>
            <mass>1.0</mass>
        </inertial>

        <collision name="collision">
        <geometry>
        <mesh>
            <scale>1 1 1</scale>
            <uri>package://inrof_sim/models/swerve/meshs/swerve_wheel.stl</uri>
        </mesh>
        </geometry>
        <surface>
            <friction>
                <ode>
                    <mu>0.3</mu>
                    <mu2>0.3</mu2>
                </ode>
            </friction>
        </surface>
        </collision>

        <visual name="visual">
        <geometry>
        <mesh>
            <scale>1 1 1</scale>
            <uri>package://inrof_sim/models/swerve/meshs/swerve_wheel.stl</uri>
        </mesh>
        </geometry>
        <material>
            <ambient>0.0 0.0 1.0 1.0</ambient>   <diffuse>0.0 0.0 1.0 1.0</diffuse>   <specular>0.1 0.1 0.1 1.0</specular> <emissive>0.0 0.0 0.0 0.0</emissive>
        </material>
        </visual>
        </link>

        <link name="wheel1">
        <pose>-0.27 0.155885 0 0 0 0</pose>
        <inertial>
            <inertia>
                <ixx>1</ixx>
                <ixy>0</ixy>
                <ixz>0</ixz>
                <iyy>1</iyy>
                <iyz>0</iyz>
                <izz>1</izz>
            </inertia>
            <mass>1.0</mass>
        </inertial>

        <collision name="collision">
        <geometry>
        <mesh>
            <scale>1 1 1</scale>
            <uri>package://inrof_sim/models/swerve/meshs/swerve_wheel.stl</uri>
        </mesh>
        </geometry>
        <surface>
            <friction>
                <ode>
                    <mu>0.3</mu>
                    <mu2>0.3</mu2>
                </ode>
            </friction>
        </surface>
        </collision>

        <visual name="visual">
        <geometry>
        <mesh>
            <scale>1 1 1</scale>
            <uri>package://inrof_sim/models/swerve/meshs/swerve_wheel.stl</uri>
        </mesh>
        </geometry>
        <material>
            <ambient>0.0 0.0 1.0 1.0</ambient>   <diffuse>0.0 0.0 1.0 1.0</diffuse>   <specular>0.1 0.1 0.1 1.0</specular> <emissive>0.0 0.0 0.0 0.0</emissive>
        </material>
        </visual>
        </link>
        
        <link name="wheel2">
        <pose>0 -0.311 0 0 0 0</pose>
        <inertial>
            <inertia>
                <ixx>1</ixx>
                <ixy>0</ixy>
                <ixz>0</ixz>
                <iyy>1</iyy>
                <iyz>0</iyz>
                <izz>1</izz>
            </inertia>
            <mass>1.0</mass>
        </inertial>

        <collision name="collision">
        <geometry>
        <mesh>
            <scale>1 1 1</scale>
            <uri>package://inrof_sim/models/swerve/meshs/swerve_wheel.stl</uri>
        </mesh>
        </geometry>
        <surface>
            <friction>
                <ode>
                    <mu>0.3</mu>
                    <mu2>0.3</mu2>
                </ode>
            </friction>
        </surface>
        </collision>

        <visual name="visual">
        <geometry>
        <mesh>
            <scale>1 1 1</scale>
            <uri>package://inrof_sim/models/swerve/meshs/swerve_wheel.stl</uri>
        </mesh>
        </geometry>
        <material>
            <ambient>0.0 0.0 1.0 1.0</ambient>   <diffuse>0.0 0.0 1.0 1.0</diffuse>   <specular>0.1 0.1 0.1 1.0</specular> <emissive>0.0 0.0 0.0 0.0</emissive>
        </material>
        </visual>
        </link>
        
        <link name="stare0">
        <pose>0.27 0.155885 0 0 0 0</pose>
        <inertial>
            <inertia>
                <ixx>1</ixx>
                <ixy>0</ixy>
                <ixz>0</ixz>
                <iyy>1</iyy>
                <iyz>0</iyz>
                <izz>1</izz>
            </inertia>
            <mass>1.0</mass>
        </inertial>

        <collision name="collision">
        <geometry>
        <mesh>
            <scale>1 1 1</scale>
            <uri>package://inrof_sim/models/swerve/meshs/swerve_stare.stl</uri>
        </mesh>
        </geometry>
        <surface>
            <friction>
                <ode>
                    <mu>0.3</mu>
                    <mu2>0.3</mu2>
                </ode>
            </friction>
        </surface>
        </collision>

        <visual name="visual">
        <geometry>
        <mesh>
            <scale>1 1 1</scale>
            <uri>package://inrof_sim/models/swerve/meshs/swerve_stare.stl</uri>
        </mesh>
        </geometry>
        <material>
            <ambient>0.0 0.0 1.0 1.0</ambient>   <diffuse>0.0 0.0 1.0 1.0</diffuse>   <specular>0.1 0.1 0.1 1.0</specular> <emissive>0.0 0.0 0.0 0.0</emissive>
        </material>
        </visual>
        </link>

        <link name="stare1">
        <pose>-0.27 0.155885 0 0 0 0</pose>
        <inertial>
            <inertia>
                <ixx>1</ixx>
                <ixy>0</ixy>
                <ixz>0</ixz>
                <iyy>1</iyy>
                <iyz>0</iyz>
                <izz>1</izz>
            </inertia>
            <mass>1.0</mass>
        </inertial>

        <collision name="collision">
        <geometry>
        <mesh>
            <scale>1 1 1</scale>
            <uri>package://inrof_sim/models/swerve/meshs/swerve_stare.stl</uri>
        </mesh>
        </geometry>
        <surface>
            <friction>
                <ode>
                    <mu>0.3</mu>
                    <mu2>0.3</mu2>
                </ode>
            </friction>
        </surface>
        </collision>

        <visual name="visual">
        <geometry>
        <mesh>
            <scale>1 1 1</scale>
            <uri>package://inrof_sim/models/swerve/meshs/swerve_stare.stl</uri>
        </mesh>
        </geometry>
        <material>
            <ambient>0.0 0.0 1.0 1.0</ambient>   <diffuse>0.0 0.0 1.0 1.0</diffuse>   <specular>0.1 0.1 0.1 1.0</specular> <emissive>0.0 0.0 0.0 0.0</emissive>
        </material>
        </visual>
        </link>
        
        <link name="stare2">
        <pose>0 -0.311 0 0 0 0</pose>
        <inertial>
            <inertia>
                <ixx>1</ixx>
                <ixy>0</ixy>
                <ixz>0</ixz>
                <iyy>1</iyy>
                <iyz>0</iyz>
                <izz>1</izz>
            </inertia>
            <mass>1.0</mass>
        </inertial>

        <collision name="collision">
        <geometry>
        <mesh>
            <scale>1 1 1</scale>
            <uri>package://inrof_sim/models/swerve/meshs/swerve_stare.stl</uri>
        </mesh>
        </geometry>
        <surface>
            <friction>
                <ode>
                    <mu>0.3</mu>
                    <mu2>0.3</mu2>
                </ode>
            </friction>
        </surface>
        </collision>

        <visual name="visual">
        <geometry>
        <mesh>
            <scale>1 1 1</scale>
            <uri>package://inrof_sim/models/swerve/meshs/swerve_stare.stl</uri>
        </mesh>
        </geometry>
        <material>
            <ambient>0.0 0.0 1.0 1.0</ambient>   <diffuse>0.0 0.0 1.0 1.0</diffuse>   <specular>0.1 0.1 0.1 1.0</specular> <emissive>0.0 0.0 0.0 0.0</emissive>
        </material>
        </visual>
        </link>

        <joint name='stare0_joint' type='revolute'>
        <parent>base_link</parent>
        <child>stare0</child>
        <axis>
            <xyz>0 0 1</xyz>
        </axis>
        </joint>

        <joint name='stare1_joint' type='revolute'>
        <parent>base_link</parent>
        <child>stare1</child>
        <axis>
            <xyz>0 0 1</xyz>
        </axis>
        </joint>

        <joint name='stare2_joint' type='revolute'>
        <parent>base_link</parent>
        <child>stare2</child>
        <axis>
            <xyz>0 0 1</xyz>
        </axis>
        </joint>

        <joint name='wheel0_joint' type='revolute'>
        <parent>stare0</parent>
        <child>wheel0</child>
        <axis>
            <xyz>0 1 0</xyz>
        </axis>
        </joint>

        <joint name='wheel1_joint' type='revolute'>
        <parent>stare1</parent>
        <child>wheel1</child>
        <axis>
            <xyz>0 1 0</xyz>
        </axis>
        </joint>

        <joint name='wheel2_joint' type='revolute'>
        <parent>stare2</parent>
        <child>wheel2</child>
        <axis>
            <xyz>0 1 0</xyz>
        </axis>
        </joint>

        <plugin name="ignition::gazebo::systems::JointController" filename="libignition-gazebo6-joint-controller-system.so">
            <joint_name>stare0_joint</joint_name>
            <topic>/swerve/cmd_pos</topic>
        </plugin>

    </model>
</sdf>